<?xml version="1.0" ?>
<!-- =================================================================================== -->
<!-- |    This document was autogenerated by xacro from zzangdol_car.urdf.xacro        | -->
<!-- |    EDITING THIS FILE BY HAND IS NOT RECOMMENDED                                 | -->
<!-- =================================================================================== -->
<robot name="zzangdol_ai_car">
  <!-- ****************** ROBOT BASE FOOTPRINT ***************************  -->
  <!-- Define the center of the main robot chassis projected on the ground -->
  <link name="base_footprint">
    <origin rpy="0 0 0" xyz="0 0 0"/>
  </link>
  <!-- The base footprint of the robot is located underneath the chassis -->
  <joint name="base_joint" type="fixed">
    <parent link="base_footprint"/>
    <child link="base_link"/>
    <origin rpy="0 0 0" xyz="0 0 0.0848"/>
  </joint>
  <!-- Body -->
  <link name="base_link">
    <visual>
      <geometry>
        <box size="0.445 0.185 0.15"/>
      </geometry>
      <material name="blue">
        <color rgba="0 0 1 1"/>
      </material>
    </visual>
  </link>
  <link name="fwheel_l_link">
    <visual>
      <origin rpy="1.5707963267948966 0 0" xyz="0 0 0"/>
      <geometry>
        <cylinder length="0.0317" radius="0.0348"/>
      </geometry>
      <material name="White">
        <color rgba="1.0 1.0 1.0 1.0"/>
      </material>
    </visual>
    <!-- <collision>
        <origin xyz="0 0 0" rpy="${M_PI/2} 0 0"/>
        <geometry>
          <cylinder radius="${wheel_radius}" length="${wheel_width}"/>
        </geometry>
      </collision>
      
      <xacro:cylinder_inertia m="110.5" r="${wheel_radius}" h="${wheel_width}"/> -->
  </link>
  <joint name="fwheel_l_steering_joint" type="revolute">
    <parent link="base_link"/>
    <child link="fwheel_l_link"/>
    <origin rpy="0 0 0" xyz="0.155 0.1075 -0.05"/>
    <limit effort="10" lower="-0.7854" upper="0.7854" velocity="1.0"/>
    <axis xyz="0 0 1"/>
  </joint>
  <link name="fwheel_r_link">
    <visual>
      <origin rpy="1.5707963267948966 0 0" xyz="0 0 0"/>
      <geometry>
        <cylinder length="0.0317" radius="0.0348"/>
      </geometry>
      <material name="White">
        <color rgba="1.0 1.0 1.0 1.0"/>
      </material>
    </visual>
    <!-- <collision>
        <origin xyz="0 0 0" rpy="${M_PI/2} 0 0"/>
        <geometry>
          <cylinder radius="${wheel_radius}" length="${wheel_width}"/>
        </geometry>
      </collision>
      
      <xacro:cylinder_inertia m="110.5" r="${wheel_radius}" h="${wheel_width}"/> -->
  </link>
  <joint name="fwheel_r_steering_joint" type="revolute">
    <parent link="base_link"/>
    <child link="fwheel_r_link"/>
    <origin rpy="0 0 0" xyz="0.155 -0.1075 -0.05"/>
    <limit effort="10" lower="-0.7854" upper="0.7854" velocity="1.0"/>
    <axis xyz="0 0 1"/>
  </joint>
  <link name="rwheel_l_link">
    <visual>
      <origin rpy="1.5707963267948966 0 0" xyz="0 0 0"/>
      <geometry>
        <cylinder length="0.0317" radius="0.0348"/>
      </geometry>
      <material name="White">
        <color rgba="1.0 1.0 1.0 1.0"/>
      </material>
    </visual>
    <!-- <collision>
        <origin xyz="0 0 0" rpy="${M_PI/2} 0 0"/>
        <geometry>
          <cylinder radius="${wheel_radius}" length="${wheel_width}"/>
        </geometry>
      </collision>
      
      <xacro:cylinder_inertia m="110.5" r="${wheel_radius}" h="${wheel_width}"/> -->
  </link>
  <joint name="rwheel_l_driving_joint" type="revolute">
    <parent link="base_link"/>
    <child link="rwheel_l_link"/>
    <origin rpy="0 0 0" xyz="-0.155 0.1075 -0.05"/>
    <limit effort="30" lower="-3.1415" upper="3.1415" velocity="5.0"/>
    <axis xyz="0 1 0"/>
  </joint>
  <link name="rwheel_r_link">
    <visual>
      <origin rpy="1.5707963267948966 0 0" xyz="0 0 0"/>
      <geometry>
        <cylinder length="0.0317" radius="0.0348"/>
      </geometry>
      <material name="White">
        <color rgba="1.0 1.0 1.0 1.0"/>
      </material>
    </visual>
    <!-- <collision>
        <origin xyz="0 0 0" rpy="${M_PI/2} 0 0"/>
        <geometry>
          <cylinder radius="${wheel_radius}" length="${wheel_width}"/>
        </geometry>
      </collision>
      
      <xacro:cylinder_inertia m="110.5" r="${wheel_radius}" h="${wheel_width}"/> -->
  </link>
  <joint name="rwheel_r_driving_joint" type="revolute">
    <parent link="base_link"/>
    <child link="rwheel_r_link"/>
    <origin rpy="0 0 0" xyz="-0.155 -0.1075 -0.05"/>
    <limit effort="30" lower="-3.1415" upper="3.1415" velocity="5.0"/>
    <axis xyz="0 1 0"/>
  </joint>
  <!-- Lidar Sensor -->
  <link name="lidar_link">
    <visual>
      <geometry>
        <cylinder length="0.01" radius="0.03"/>
      </geometry>
      <material name="red">
        <color rgba="1 0 0 1"/>
      </material>
    </visual>
  </link>
  <joint name="lidar_joint" type="fixed">
    <origin rpy="0 0 0" xyz="0.15 0 0.1"/>
    <parent link="base_link"/>
    <child link="lidar_link"/>
  </joint>
  <!-- IMU -->
  <link name="imu_link">
    <visual>
      <geometry>
        <box size="0.01 0.01 0.001"/>
      </geometry>
      <material name="green">
        <color rgba="0 1 0 1"/>
      </material>
    </visual>
  </link>
  <joint name="imu_joint" type="fixed">
    <origin rpy="0 0 0" xyz="0.09 0 0.08"/>
    <parent link="base_link"/>
    <child link="imu_link"/>
  </joint>
</robot>

